Workbook

Sheet Instructions
A1: Expo 2027 Belgrade — Operations Project Plan: Instructions & Legend
A2: This tab explains how the plan is structured and how the Consultant Milestones section should be kept up to date. Read this before editing the plan.
A4: Maintaining the Consultant Milestones Section | J4: Legend: REF Coding Scheme
A5: The Consultant Milestones section tracks all S21 consultant deliverables against the project plan, and must be kept current on a weekly basis so that progress reporting reflects an accurate, real-time picture of delivery. | J5: REF Format | K5: Row Type | L5: Description | O5: Row Colour
A6: Every deliverable and subtask row must carry a date, even where that date is not yet firm. Where a date is tentative, it should still be entered so the schedule remains usable, with a comment added to the cell noting that the date is to be confirmed. This ensures no row is left undated simply because full certainty hasn't been reached. | J6: KM.# | K6: Key Milestone | L6: Top-level programme milestone
A7: Where work has already been completed, it should be added to the plan retrospectively with its actual start and end dates, rather than left blank. The plan is intended to reflect the full history of delivery, not just work that is currently in progress. | J7: CM.DEPT.## | K7: Consultant Milestone (S21) | L7: S21 consultant deliverable, linked to a Key Milestone
A8: Any document produced as part of a deliverable should be referenced in the row, noting that it is stored on the CEG share drive. This keeps the plan as a reliable index of where supporting evidence can be found, without duplicating files across locations. | J8: DEPT-T## | K8: Department Task | L8: Department-owned task
A9: When new work begins under an existing Consultant Milestone, it should be captured as a new sub-line nested beneath that milestone, rather than by editing the milestone row itself. This preserves the milestone as a stable reference point while still allowing the detail beneath it to grow over time. | J9: DEPT-S##.n | K9: Department Subtask | L9: Department-owned subtask, nested under a Task
A10: Finally, by end of day Wednesday each week, every open task must have its status corrected to reflect current progress, with a short written update entered in the "This Week's Update" column. This weekly discipline is what allows the plan to feed directly into the Crowded Event Weekly Report and other leadership reporting without needing to be re-validated each time.
J11: Legend: Status / RAG
A12: Maintaining the Key Milestones Section | J12: Status | L12: Meaning
A13: Key Milestones represent the top-level programme deliverables tracked by the IDR, and this plan needs to stay aligned with that external master so that departmental delivery is always being measured against the milestones that actually matter at programme level. | K13: Complete | L13: Deliverable fully complete
A14: Updates to Key Milestones are currently shared manually to the IDR's master tracker rather than through an automated feed. This means the version held here should be treated as the working copy, with the IDR's master as the single source of truth once an update has been shared — any discrepancy between the two should be resolved in favour of the IDR master. | K14: On Track | L14: Progressing to plan, no material risk
A15: Dates against each Key Milestone should be driven by the department, not set independently within the plan. The date reflects the department's own committed timeline for that deliverable, which keeps ownership and accountability where it belongs and ensures the plan is targeting the right deliverables rather than dates the consultant has assumed on the department's behalf. | K15: At Risk | L15: Risk to schedule/scope — needs attention
K16: Not Started | L16: Work has not yet begun
K17: No Update Received | L17: No SME/department update provided this cycle
A20: Key Milestones
A36: Colour Conventions

Sheet Tracker
A2: Expo 2027 Belgrade — Operations Project Plan | L2: Status Legend: | N2: Complete | O2: Key Milestones
N3: At Risk | O3: SME Milestones (S21)
A4: Project: | C4: Belgrade 2027 | N4: No Update Received | O4: Department Task
A5: Division: | C5: Operations | N5: On Track | O5: Subtasks
A6: Scope: | C6: Operational Departments | N6: Not Started
A7: Last Updated: | C7: 46231
A8: Tier | B8: Type | C8: Sector | D8: Department | E8: Sub-Team | F8: REF | G8: Deliverable | H8: Description of Service | I8: Owner / Support | J8: SME / SME | K8: Start Date | L8: End Date | M8: Status | N8: Comment | O8: Last Reported (Week Ending) | P8: % Complete | Q8: This Week's Update (S21) | R8: Evidence/Link to Docs
A9: 1 | B9: Key Milestone | C9: Operations | D9: Accreditation (ACR) | F9: KM.100 | G9: Event - Time Accreditation System - Go-Live | I9: Department Led | L9: 46296 | M9: At Risk | N9: Why are we printing ET so early? Or this is for bump in passes?
A10: 1 | B10: Key Milestone | C10: Operations | D10: Accreditation (ACR) | F10: KM.110 | G10: Event Time Operations & Programme Closure - Completed | I10: Department Led | L10: 46399 | M10: On Track
A11: 1 | B11: Key Milestone | C11: Operations | D11: Accreditation (ACR) | F11: KM.140 | G11: Accreditation Application Process Commence | I11: Department Led | L11: 46296 | M11: On Track
A12: 1 | B12: Key Milestone | C12: Operations | D12: Accreditation (ACR) | F12: KM.144 | G12: Accreditation Centre Fully Operational | I12: Department Led | L12: 46296 | M12: On Track
A13: 1 | B13: Key Milestone | C13: Operations | D13: Accreditation (ACR) | F13: NEW | G13: Bump In passes Live | I13: Department Led | M13: No Update Received
A14: 1 | B14: Key Milestone | C14: Operations | D14: Accreditation (ACR) | F14: NEW | G14: Event Time Accreditation Stands Up | I14: Department Led | M14: No Update Received
A15: 1 | B15: Key Milestone | C15: Operations | D15: Accreditation (ACR) | F15: NEW | G15: Event Time Accrediation Stands Down | I15: Department Led | M15: No Update Received
A16: 1 | B16: Key Milestone | C16: Operations | D16: Accreditation (ACR) | F16: NEW | G16: Bump Out Passes Live | M16: No Update Received
A17: 1 | B17: Key Milestone | C17: Operations | D17: Accreditation (ACR) | F17: NEW | G17: Zoning Plan & Privilege Matrix Approved | H17: Zoning plan and access privilege matrix signed off. | I17: Department Led | L17: 46266 | M17: Not Started | N17: Proposed new milestone - pending review
A18: 1 | B18: Key Milestone | C18: Operations | D18: Accreditation (ACR) | F18: NEW | G18: Accreditation System & Printers Procured | H18: Accreditation management system and printing hardware procured. | I18: Department Led | L18: 46249 | M18: Not Started | N18: Proposed new milestone - pending review
A19: 1 | B19: Key Milestone | C19: Operations | D19: Accreditation (ACR) | F19: NEW | G19: Accreditation Categories & Types Confirmed | H19: Full set of accreditation types and categories confirmed. | I19: Department Led | L19: 46235 | M19: Not Started | N19: Proposed new milestone - pending review
A20: 2 | B20: SME Milestone | C20: Operations | D20: Accreditation (ACR) | F20: CM.ACR.01 | G20: Support with the establishment of the Accreditation Governance Framework | H20: Establish governance, reporting structures, decision-making processes, RACI and programme assurance approach | I20: SME-Led (S21) | M20: TBC if this is applicable
A21: 2 | B21: SME Milestone | C21: Operations | D21: Accreditation (ACR) | F21: CM.ACR.02 | G21: Accreditation Programme Review & Readiness Assessment | H21: Review strategy, delivery roadmap, milestones, risks, dependencies and operational gaps | I21: SME-Led (S21) | M21: TBC if this is applicable
A22: 2 | B22: SME Milestone | C22: Operations | D22: Accreditation (ACR) | F22: CM.ACR.03 | G22: Accreditation Access Management Framework | H22: Review zoning plans, privilege matrices, access rights, access boards and approval processes | I22: SME-Led (S21) | M22: TBC if this is applicable
A23: 2 | B23: SME Milestone | C23: Operations | D23: Accreditation (ACR) | F23: CM.ACR.04 | G23: Accreditation System Implementation & Readiness | H23: Provide assurance on system procurement, configuration, integration, testing and operational suitability | I23: SME-Led (S21) | M23: TBC if this is applicable
A24: 2 | B24: SME Milestone | C24: Operations | D24: Accreditation (ACR) | F24: CM.ACR.05 | G24: Accreditation Compliance & Data Management Processes | H24: Support GDPR, background checks, data handling, security compliance and governance requirements | I24: SME-Led (S21) | M24: TBC if this is applicable
A25: 2 | B25: SME Milestone | C25: Operations | D25: Accreditation (ACR) | F25: CM.ACR.06 | G25: Accreditation Operational Planning | H25: Review accreditation types, pass design, registration processes, ALO mobilisation and accreditation centre operations | I25: SME-Led (S21) | M25: TBC if this is applicable
A26: 2 | B26: SME Milestone | C26: Operations | D26: Accreditation (ACR) | F26: CM.ACR.07 | G26: Accreditation Operational Readiness Reviews | H26: Assess readiness against agreed criteria, facilitate stakeholder reviews and identify outstanding actions | I26: SME-Led (S21) | M26: TBC if this is applicable
A27: 2 | B27: SME Milestone | C27: Operations | D27: Accreditation (ACR) | F27: CM.ACR.08 | G27: Bump-In/Bump-Out Strategy | H27: Review contractor access strategy, temporary accreditation processes and operational deployment plans | I27: SME-Led (S21) | M27: TBC if this is applicable
A28: 1 | B28: Key Milestone | C28: Operations | D28: C4i | F28: NEW | G28: MOC Space Allocation Finalised | I28: Department Led | M28: No Update Received | N28: I wouldn't use it as a key milestone. Instead space ready for operations and handed over to Space owner.
A29: 1 | B29: Key Milestone | C29: Operations | D29: C4i | F29: NEW | G29: Incident Logging & Reporting Live | I29: Department Led | M29: No Update Received
A30: 1 | B30: Key Milestone | C30: Operations | D30: C4i | F30: NEW | G30: MOC Stands Up | I30: Department Led | L30: 01.May.27 | M30: No Update Received
A31: 1 | B31: Key Milestone | C31: Operations | D31: C4i | F31: NEW | G31: MOC Stands Down | I31: Department Led | M31: No Update Received
A32: 1 | B32: Key Milestone | C32: Operations | D32: C4i | F32: NEW | G32: C4i Framework Approved | H32: Overarching Command, Control, Communications and Information framework signed off. | I32: Department Led | L32: 46266 | M32: Not Started | N32: Proposed new milestone - pending review
A33: 1 | B33: Key Milestone | C33: Operations | D33: C4i | F33: NEW | G33: MOC Operating Model Approved | H33: Main Operations Centre operating model agreed. | I33: Department Led | L33: 46280 | M33: Not Started | N33: Proposed new milestone - pending review
A34: 1 | B34: Key Milestone | C34: Operations | D34: C4i | F34: NEW | G34: Event-Time Governance & Delegations Framework Signed Off | H34: Decision-making authority and delegations for event time agreed. | I34: Department Led | L34: 46296 | M34: Not Started | N34: Proposed new milestone - pending review
A35: 1 | B35: Key Milestone | C35: Operations | D35: C4i | F35: NEW | G35: C4i Communications & Information Management Plan Approved | H35: Plan for communications and information flow across event time agreed. | I35: Department Led | L35: 46310 | M35: Not Started | N35: Proposed new milestone - pending review
A36: 1 | B36: Key Milestone | C36: Operations | D36: C4i | F36: NEW | G36: External Stakeholder Interface Protocols Agreed | H36: Interface protocols with external agencies and stakeholders confirmed. | I36: Department Led | L36: 46327 | M36: Not Started | N36: Proposed new milestone - pending review
A37: 1 | B37: Key Milestone | C37: Operations | D37: C4i | F37: NEW | G37: MOC Readiness Testing Programme Complete | H37: Testing programme for MOC systems and processes complete. | I37: Department Led | L37: 46447 | M37: Not Started | N37: Proposed new milestone - pending review
A38: 1 | B38: Key Milestone | C38: Operations | D38: C4i | F38: NEW | G38: C4i Stakeholder Integration Complete | H38: Integration of departmental desks and functional interfaces within the MOC complete. | I38: Department Led | L38: 46461 | M38: Not Started | N38: Proposed new milestone - pending review
A39: 2 | B39: SME Milestone | C39: Operations | D39: C4i | F39: CM.C4i.01 | G39: C4i Governance & Operating Frameworks | H39: Establish C4i governance, command and control principles, operating model, decision-making structures, reporting processes and operational interfaces. | I39: SME-Led (S21) | J39: Teymur | K39: 46223 | L39: 46295 | M39: On Track
A40: 3 | B40: SME Milestone | C40: Operations | D40: C4i | F40: CM.C4i.01.1 | G40: C4i baseline review and gap analysis complete | H40: Review the C4i Bridging Document V0, Belgrade ConOps, existing MOC design and comparator material against EX27 operational requirements, and issue the gap position. | I40: SME-Led (S21) | J40: Teymur | K40: 46209 | L40: 46234 | M40: Complete | N40: Integrate-first approach: baseline the incumbent position before proposing change.
A41: 3 | B41: SME Milestone | C41: Operations | D41: C4i | F41: CM.C4i.01.2 | G41: C4i Framework V1 produced | H41: Produce the C4i Framework covering purpose, principles, command tiers, operations centre architecture and the severity and escalation model. | I41: SME-Led (S21) | J41: Teymur | K41: 46223 | L41: 46252 | M41: On Track | N41: Anchor date for V1 is 18-Aug-26. Sections 1 to 4 complete at V1; Sections 5 to 9 stubbed pending the structural rulings at CM.C4i.01.2.3.
...

Sheet Sheet2
B1: Complete | F1: Key Milestones
B2: At Risk | F2: Consultant Milestones (S21)
B3: No Update Received | F3: Task
B4: On Track | F4: Subtasks
B5: Not Started

Sheet Timeline
A1: EX27 Operations Timeline
A2: Pulled live from Tracker. Formulas update when Tracker changes. | H2: In progress | M2: At risk / blocked | R2: Complete | W2: Workstream summary | AB2: Current week
G4: Sep 2025 | H4: Oct 2025 | L4: Nov 2025 | P4: Dec 2025 | U4: Jan 2026 | Y4: Feb 2026 | AC4: Mar 2026 | AH4: Apr 2026 | AL4: May 2026 | AP4: Jun 2026 | AU4: Jul 2026 | AY4: Aug 2026 | BD4: Sep 2026 | BH4: Oct 2026 | BL4: Nov 2026 | BQ4: Dec 2026 | BU4: Jan 2027 | BY4: Feb 2027 | CC4: Mar 2027 | CH4: Apr 2027 | CL4: May 2027 | CQ4: Jun 2027 | CU4: Jul 2027 | CY4: Aug 2027 | DD4: Sep 2027 | DH4: Oct 2027 | DL4: Nov 2027 | DQ4: Dec 2027
A5: REF | B5: Task Name | C5: Workstream | D5: Owner | E5: Start | F5: Finish | G5: 45929 | H5: 45936 | I5: 45943 | J5: 45950 | K5: 45957 | L5: 45964 | M5: 45971 | N5: 45978 | O5: 45985 | P5: 45992 | Q5: 45999 | R5: 46006 | S5: 46013 | T5: 46020 | U5: 46027 | V5: 46034 | W5: 46041 | X5: 46048 | Y5: 46055 | Z5: 46062 | AA5: 46069 | AB5: 46076 | AC5: 46083 | AD5: 46090 | AE5: 46097 | AF5: 46104 | AG5: 46111 | AH5: 46118 | AI5: 46125 | AJ5: 46132 | AK5: 46139 | AL5: 46146 | AM5: 46153 | AN5: 46160 | AO5: 46167 | AP5: 46174 | AQ5: 46181 | AR5: 46188 | AS5: 46195 | AT5: 46202 | AU5: 46209 | AV5: 46216 | AW5: 46223 | AX5: 46230 | AY5: 46237 | AZ5: 46244 | BA5: 46251 | BB5: 46258 | BC5: 46265 | BD5: 46272 | BE5: 46279 | BF5: 46286 | BG5: 46293 | BH5: 46300 | BI5: 46307 | BJ5: 46314 | BK5: 46321 | BL5: 46328 | BM5: 46335 | BN5: 46342 | BO5: 46349 | BP5: 46356 | BQ5: 46363 | BR5: 46370 | BS5: 46377 | BT5: 46384 | BU5: 46391 | BV5: 46398 | BW5: 46405 | BX5: 46412 | BY5: 46419 | BZ5: 46426 | CA5: 46433 | CB5: 46440 | CC5: 46447 | CD5: 46454 | CE5: 46461 | CF5: 46468 | CG5: 46475 | CH5: 46482 | CI5: 46489 | CJ5: 46496 | CK5: 46503 | CL5: 46510 | CM5: 46517 | CN5: 46524 | CO5: 46531 | CP5: 46538 | CQ5: 46545 | CR5: 46552 | CS5: 46559 | CT5: 46566 | CU5: 46573 | CV5: 46580 | CW5: 46587 | CX5: 46594 | CY5: 46601 | CZ5: 46608 | DA5: 46615 | DB5: 46622 | DC5: 46629 | DD5: 46636 | DE5: 46643 | DF5: 46650 | DG5: 46657 | DH5: 46664 | DI5: 46671 | DJ5: 46678 | DK5: 46685 | DL5: 46692 | DM5: 46699 | DN5: 46706 | DO5: 46713 | DP5: 46720 | DQ5: 46727 | DR5: 46734 | DS5: 46741 | DT5: 46748 | DU5: StatusRef
B6: Accreditation (ACR) | C6: Accreditation (ACR) | E6: =IFERROR(_xlfn.MINIFS(E7:E25,E7:E25,">0"),0) -> 46235 | F6: =IFERROR(_xlfn.MAXIFS(F7:F25,F7:F25,">0"),0) -> 46399 | DU6: WORKSTREAM_SUMMARY
A7: =Tracker!F9 -> KM.100 | B7: =Tracker!G9 -> Event - Time Accreditation System - Go-Live | C7: =TRIM(Tracker!D9) -> Accreditation (ACR) | D7: =IF(TRIM(Tracker!J9)="",Tracker!I9,Tracker!J9) -> Department Led | E7: =IF(ISNUMBER(Tracker!K9),Tracker!K9,IF(ISNUMBER(Tracker!L9),Tracker!L9,0)) -> 46296 | F7: =IF(ISNUMBER(Tracker!L9),Tracker!L9,IF(ISNUMBER(Tracker!K9),Tracker!K9,0)) -> 46296 | DU7: =Tracker!M9 -> At Risk
A8: =Tracker!F10 -> KM.110 | B8: =Tracker!G10 -> Event Time Operations & Programme Closure - Completed | C8: =TRIM(Tracker!D10) -> Accreditation (ACR) | D8: =IF(TRIM(Tracker!J10)="",Tracker!I10,Tracker!J10) -> Department Led | E8: =IF(ISNUMBER(Tracker!K10),Tracker!K10,IF(ISNUMBER(Tracker!L10),Tracker!L10,0)) -> 46399 | F8: =IF(ISNUMBER(Tracker!L10),Tracker!L10,IF(ISNUMBER(Tracker!K10),Tracker!K10,0)) -> 46399 | DU8: =Tracker!M10 -> On Track
A9: =Tracker!F11 -> KM.140 | B9: =Tracker!G11 -> Accreditation Application Process Commence | C9: =TRIM(Tracker!D11) -> Accreditation (ACR) | D9: =IF(TRIM(Tracker!J11)="",Tracker!I11,Tracker!J11) -> Department Led | E9: =IF(ISNUMBER(Tracker!K11),Tracker!K11,IF(ISNUMBER(Tracker!L11),Tracker!L11,0)) -> 46296 | F9: =IF(ISNUMBER(Tracker!L11),Tracker!L11,IF(ISNUMBER(Tracker!K11),Tracker!K11,0)) -> 46296 | DU9: =Tracker!M11 -> On Track
A10: =Tracker!F12 -> KM.144 | B10: =Tracker!G12 -> Accreditation Centre Fully Operational | C10: =TRIM(Tracker!D12) -> Accreditation (ACR) | D10: =IF(TRIM(Tracker!J12)="",Tracker!I12,Tracker!J12) -> Department Led | E10: =IF(ISNUMBER(Tracker!K12),Tracker!K12,IF(ISNUMBER(Tracker!L12),Tracker!L12,0)) -> 46296 | F10: =IF(ISNUMBER(Tracker!L12),Tracker!L12,IF(ISNUMBER(Tracker!K12),Tracker!K12,0)) -> 46296 | DU10: =Tracker!M12 -> On Track
A11: =Tracker!F13 -> NEW | B11: =Tracker!G13 -> Bump In passes Live | C11: =TRIM(Tracker!D13) -> Accreditation (ACR) | D11: =IF(TRIM(Tracker!J13)="",Tracker!I13,Tracker!J13) -> Department Led | E11: =IF(ISNUMBER(Tracker!K13),Tracker!K13,IF(ISNUMBER(Tracker!L13),Tracker!L13,0)) -> 0 | F11: =IF(ISNUMBER(Tracker!L13),Tracker!L13,IF(ISNUMBER(Tracker!K13),Tracker!K13,0)) -> 0 | DU11: =Tracker!M13 -> No Update Received
A12: =Tracker!F14 -> NEW | B12: =Tracker!G14 -> Event Time Accreditation Stands Up | C12: =TRIM(Tracker!D14) -> Accreditation (ACR) | D12: =IF(TRIM(Tracker!J14)="",Tracker!I14,Tracker!J14) -> Department Led | E12: =IF(ISNUMBER(Tracker!K14),Tracker!K14,IF(ISNUMBER(Tracker!L14),Tracker!L14,0)) -> 0 | F12: =IF(ISNUMBER(Tracker!L14),Tracker!L14,IF(ISNUMBER(Tracker!K14),Tracker!K14,0)) -> 0 | DU12: =Tracker!M14 -> No Update Received
A13: =Tracker!F15 -> NEW | B13: =Tracker!G15 -> Event Time Accrediation Stands Down | C13: =TRIM(Tracker!D15) -> Accreditation (ACR) | D13: =IF(TRIM(Tracker!J15)="",Tracker!I15,Tracker!J15) -> Department Led | E13: =IF(ISNUMBER(Tracker!K15),Tracker!K15,IF(ISNUMBER(Tracker!L15),Tracker!L15,0)) -> 0 | F13: =IF(ISNUMBER(Tracker!L15),Tracker!L15,IF(ISNUMBER(Tracker!K15),Tracker!K15,0)) -> 0 | DU13: =Tracker!M15 -> No Update Received
A14: =Tracker!F16 -> NEW | B14: =Tracker!G16 -> Bump Out Passes Live | C14: =TRIM(Tracker!D16) -> Accreditation (ACR) | D14: =IF(TRIM(Tracker!J16)="",Tracker!I16,Tracker!J16) -> 0 | E14: =IF(ISNUMBER(Tracker!K16),Tracker!K16,IF(ISNUMBER(Tracker!L16),Tracker!L16,0)) -> 0 | F14: =IF(ISNUMBER(Tracker!L16),Tracker!L16,IF(ISNUMBER(Tracker!K16),Tracker!K16,0)) -> 0 | DU14: =Tracker!M16 -> No Update Received
A15: =Tracker!F17 -> NEW | B15: =Tracker!G17 -> Zoning Plan & Privilege Matrix Approved | C15: =TRIM(Tracker!D17) -> Accreditation (ACR) | D15: =IF(TRIM(Tracker!J17)="",Tracker!I17,Tracker!J17) -> Department Led | E15: =IF(ISNUMBER(Tracker!K17),Tracker!K17,IF(ISNUMBER(Tracker!L17),Tracker!L17,0)) -> 46266 | F15: =IF(ISNUMBER(Tracker!L17),Tracker!L17,IF(ISNUMBER(Tracker!K17),Tracker!K17,0)) -> 46266 | DU15: =Tracker!M17 -> Not Started
A16: =Tracker!F18 -> NEW | B16: =Tracker!G18 -> Accreditation System & Printers Procured | C16: =TRIM(Tracker!D18) -> Accreditation (ACR) | D16: =IF(TRIM(Tracker!J18)="",Tracker!I18,Tracker!J18) -> Department Led | E16: =IF(ISNUMBER(Tracker!K18),Tracker!K18,IF(ISNUMBER(Tracker!L18),Tracker!L18,0)) -> 46249 | F16: =IF(ISNUMBER(Tracker!L18),Tracker!L18,IF(ISNUMBER(Tracker!K18),Tracker!K18,0)) -> 46249 | DU16: =Tracker!M18 -> Not Started
A17: =Tracker!F19 -> NEW | B17: =Tracker!G19 -> Accreditation Categories & Types Confirmed | C17: =TRIM(Tracker!D19) -> Accreditation (ACR) | D17: =IF(TRIM(Tracker!J19)="",Tracker!I19,Tracker!J19) -> Department Led | E17: =IF(ISNUMBER(Tracker!K19),Tracker!K19,IF(ISNUMBER(Tracker!L19),Tracker!L19,0)) -> 46235 | F17: =IF(ISNUMBER(Tracker!L19),Tracker!L19,IF(ISNUMBER(Tracker!K19),Tracker!K19,0)) -> 46235 | DU17: =Tracker!M19 -> Not Started
A18: =Tracker!F20 -> CM.ACR.01 | B18: =Tracker!G20 -> Support with the establishment of the Accreditation Governance Framework | C18: =TRIM(Tracker!D20) -> Accreditation (ACR) | D18: =IF(TRIM(Tracker!J20)="",Tracker!I20,Tracker!J20) -> SME-Led (S21) | E18: =IF(ISNUMBER(Tracker!K20),Tracker!K20,IF(ISNUMBER(Tracker!L20),Tracker!L20,0)) -> 0 | F18: =IF(ISNUMBER(Tracker!L20),Tracker!L20,IF(ISNUMBER(Tracker!K20),Tracker!K20,0)) -> 0 | DU18: =Tracker!M20 -> TBC if this is applicable
... A25: =Tracker!F27 -> CM.ACR.08 | B25: =Tracker!G27 -> Bump-In/Bump-Out Strategy | C25: =TRIM(Tracker!D27) -> Accreditation (ACR) | D25: =IF(TRIM(Tracker!J27)="",Tracker!I27,Tracker!J27) -> SME-Led (S21) | E25: =IF(ISNUMBER(Tracker!K27),Tracker!K27,IF(ISNUMBER(Tracker!L27),Tracker!L27,0)) -> 0 | F25: =IF(ISNUMBER(Tracker!L27),Tracker!L27,IF(ISNUMBER(Tracker!K27),Tracker!K27,0)) -> 0 | DU25: =Tracker!M27 -> TBC if this is applicable
B26: C4i | C26: C4i | E26: =IFERROR(_xlfn.MINIFS(E27:E150,E27:E150,">0"),0) -> 46209 | F26: =IFERROR(_xlfn.MAXIFS(F27:F150,F27:F150,">0"),0) -> 46508 | DU26: WORKSTREAM_SUMMARY
A27: =Tracker!F28 -> NEW | B27: =Tracker!G28 -> MOC Space Allocation Finalised | C27: =TRIM(Tracker!D28) -> C4i | D27: =IF(TRIM(Tracker!J28)="",Tracker!I28,Tracker!J28) -> Department Led | E27: =IF(ISNUMBER(Tracker!K28),Tracker!K28,IF(ISNUMBER(Tracker!L28),Tracker!L28,0)) -> 0 | F27: =IF(ISNUMBER(Tracker!L28),Tracker!L28,IF(ISNUMBER(Tracker!K28),Tracker!K28,0)) -> 0 | DU27: =Tracker!M28 -> No Update Received
A28: =Tracker!F29 -> NEW | B28: =Tracker!G29 -> Incident Logging & Reporting Live | C28: =TRIM(Tracker!D29) -> C4i | D28: =IF(TRIM(Tracker!J29)="",Tracker!I29,Tracker!J29) -> Department Led | E28: =IF(ISNUMBER(Tracker!K29),Tracker!K29,IF(ISNUMBER(Tracker!L29),Tracker!L29,0)) -> 0 | F28: =IF(ISNUMBER(Tracker!L29),Tracker!L29,IF(ISNUMBER(Tracker!K29),Tracker!K29,0)) -> 0 | DU28: =Tracker!M29 -> No Update Received
A29: =Tracker!F30 -> NEW | B29: =Tracker!G30 -> MOC Stands Up | C29: =TRIM(Tracker!D30) -> C4i | D29: =IF(TRIM(Tracker!J30)="",Tracker!I30,Tracker!J30) -> Department Led | E29: =IF(ISNUMBER(Tracker!K30),Tracker!K30,IF(ISNUMBER(Tracker!L30),Tracker!L30,0)) -> 0 | F29: =IF(ISNUMBER(Tracker!L30),Tracker!L30,IF(ISNUMBER(Tracker!K30),Tracker!K30,0)) -> 0 | DU29: =Tracker!M30 -> No Update Received
A30: =Tracker!F31 -> NEW | B30: =Tracker!G31 -> MOC Stands Down | C30: =TRIM(Tracker!D31) -> C4i | D30: =IF(TRIM(Tracker!J31)="",Tracker!I31,Tracker!J31) -> Department Led | E30: =IF(ISNUMBER(Tracker!K31),Tracker!K31,IF(ISNUMBER(Tracker!L31),Tracker!L31,0)) -> 0 | F30: =IF(ISNUMBER(Tracker!L31),Tracker!L31,IF(ISNUMBER(Tracker!K31),Tracker!K31,0)) -> 0 | DU30: =Tracker!M31 -> No Update Received
A31: =Tracker!F32 -> NEW | B31: =Tracker!G32 -> C4i Framework Approved | C31: =TRIM(Tracker!D32) -> C4i | D31: =IF(TRIM(Tracker!J32)="",Tracker!I32,Tracker!J32) -> Department Led | E31: =IF(ISNUMBER(Tracker!K32),Tracker!K32,IF(ISNUMBER(Tracker!L32),Tracker!L32,0)) -> 46266 | F31: =IF(ISNUMBER(Tracker!L32),Tracker!L32,IF(ISNUMBER(Tracker!K32),Tracker!K32,0)) -> 46266 | DU31: =Tracker!M32 -> Not Started
A32: =Tracker!F33 -> NEW | B32: =Tracker!G33 -> MOC Operating Model Approved | C32: =TRIM(Tracker!D33) -> C4i | D32: =IF(TRIM(Tracker!J33)="",Tracker!I33,Tracker!J33) -> Department Led | E32: =IF(ISNUMBER(Tracker!K33),Tracker!K33,IF(ISNUMBER(Tracker!L33),Tracker!L33,0)) -> 46280 | F32: =IF(ISNUMBER(Tracker!L33),Tracker!L33,IF(ISNUMBER(Tracker!K33),Tracker!K33,0)) -> 46280 | DU32: =Tracker!M33 -> Not Started
A33: =Tracker!F34 -> NEW | B33: =Tracker!G34 -> Event-Time Governance & Delegations Framework Signed Off | C33: =TRIM(Tracker!D34) -> C4i | D33: =IF(TRIM(Tracker!J34)="",Tracker!I34,Tracker!J34) -> Department Led | E33: =IF(ISNUMBER(Tracker!K34),Tracker!K34,IF(ISNUMBER(Tracker!L34),Tracker!L34,0)) -> 46296 | F33: =IF(ISNUMBER(Tracker!L34),Tracker!L34,IF(ISNUMBER(Tracker!K34),Tracker!K34,0)) -> 46296 | DU33: =Tracker!M34 -> Not Started
A34: =Tracker!F35 -> NEW | B34: =Tracker!G35 -> C4i Communications & Information Management Plan Approved | C34: =TRIM(Tracker!D35) -> C4i | D34: =IF(TRIM(Tracker!J35)="",Tracker!I35,Tracker!J35) -> Department Led | E34: =IF(ISNUMBER(Tracker!K35),Tracker!K35,IF(ISNUMBER(Tracker!L35),Tracker!L35,0)) -> 46310 | F34: =IF(ISNUMBER(Tracker!L35),Tracker!L35,IF(ISNUMBER(Tracker!K35),Tracker!K35,0)) -> 46310 | DU34: =Tracker!M35 -> Not Started
A35: =Tracker!F36 -> NEW | B35: =Tracker!G36 -> External Stakeholder Interface Protocols Agreed | C35: =TRIM(Tracker!D36) -> C4i | D35: =IF(TRIM(Tracker!J36)="",Tracker!I36,Tracker!J36) -> Department Led | E35: =IF(ISNUMBER(Tracker!K36),Tracker!K36,IF(ISNUMBER(Tracker!L36),Tracker!L36,0)) -> 46327 | F35: =IF(ISNUMBER(Tracker!L36),Tracker!L36,IF(ISNUMBER(Tracker!K36),Tracker!K36,0)) -> 46327 | DU35: =Tracker!M36 -> Not Started
A36: =Tracker!F37 -> NEW | B36: =Tracker!G37 -> MOC Readiness Testing Programme Complete | C36: =TRIM(Tracker!D37) -> C4i | D36: =IF(TRIM(Tracker!J37)="",Tracker!I37,Tracker!J37) -> Department Led | E36: =IF(ISNUMBER(Tracker!K37),Tracker!K37,IF(ISNUMBER(Tracker!L37),Tracker!L37,0)) -> 46447 | F36: =IF(ISNUMBER(Tracker!L37),Tracker!L37,IF(ISNUMBER(Tracker!K37),Tracker!K37,0)) -> 46447 | DU36: =Tracker!M37 -> Not Started
A37: =Tracker!F38 -> NEW | B37: =Tracker!G38 -> C4i Stakeholder Integration Complete | C37: =TRIM(Tracker!D38) -> C4i | D37: =IF(TRIM(Tracker!J38)="",Tracker!I38,Tracker!J38) -> Department Led | E37: =IF(ISNUMBER(Tracker!K38),Tracker!K38,IF(ISNUMBER(Tracker!L38),Tracker!L38,0)) -> 46461 | F37: =IF(ISNUMBER(Tracker!L38),Tracker!L38,IF(ISNUMBER(Tracker!K38),Tracker!K38,0)) -> 46461 | DU37: =Tracker!M38 -> Not Started
A38: =Tracker!F39 -> CM.C4i.01 | B38: =Tracker!G39 -> C4i Governance & Operating Frameworks | C38: =TRIM(Tracker!D39) -> C4i | D38: =IF(TRIM(Tracker!J39)="",Tracker!I39,Tracker!J39) -> Teymur | E38: =IF(ISNUMBER(Tracker!K39),Tracker!K39,IF(ISNUMBER(Tracker!L39),Tracker!L39,0)) -> 46223 | F38: =IF(ISNUMBER(Tracker!L39),Tracker!L39,IF(ISNUMBER(Tracker!K39),Tracker!K39,0)) -> 46295 | DU38: =Tracker!M39 -> On Track
... A150: =Tracker!F151 -> CM.C4i.10.5 | B150: =Tracker!G151 -> Intellectual Property and document handover process agreed and executed | C150: =TRIM(Tracker!D151) -> C4i | D150: =IF(TRIM(Tracker!J151)="",Tracker!I151,Tracker!J151) -> Teymur | E150: =IF(ISNUMBER(Tracker!K151),Tracker!K151,IF(ISNUMBER(Tracker!L151),Tracker!L151,0)) -> 46266 | F150: =IF(ISNUMBER(Tracker!L151),Tracker!L151,IF(ISNUMBER(Tracker!K151),Tracker!K151,0)) -> 46507 | DU150: =Tracker!M151 -> Not Started
B151: Design & Construction | C151: Design & Construction | E151: =IFERROR(_xlfn.MINIFS(E152:E152,E152:E152,">0"),0) -> 0 | F151: =IFERROR(_xlfn.MAXIFS(F152:F152,F152:F152,">0"),0) -> 0 | DU151: WORKSTREAM_SUMMARY
A152: =Tracker!F152 -> 0 | B152: =Tracker!G152 -> Site Handover Plan | C152: =TRIM(Tracker!D152) -> Design & Construction | D152: =IF(TRIM(Tracker!J152)="",Tracker!I152,Tracker!J152) -> David | E152: =IF(ISNUMBER(Tracker!K152),Tracker!K152,IF(ISNUMBER(Tracker!L152),Tracker!L152,0)) -> 0 | F152: =IF(ISNUMBER(Tracker!L152),Tracker!L152,IF(ISNUMBER(Tracker!K152),Tracker!K152,0)) -> 0 | DU152: =Tracker!M152 -> Complete
B153: Event & Venue Management | C153: Event & Venue Management | E153: =IFERROR(_xlfn.MINIFS(E154:E159,E154:E159,">0"),0) -> 46296 | F153: =IFERROR(_xlfn.MAXIFS(F154:F159,F154:F159,">0"),0) -> 46508 | DU153: WORKSTREAM_SUMMARY
A154: =Tracker!F153 -> KM.116 | B154: =Tracker!G153 -> Final Zone Operating Plan Version Approved | C154: =TRIM(Tracker!D153) -> Event & Venue Management | D154: =IF(TRIM(Tracker!J153)="",Tracker!I153,Tracker!J153) -> Department Led | E154: =IF(ISNUMBER(Tracker!K153),Tracker!K153,IF(ISNUMBER(Tracker!L153),Tracker!L153,0)) -> 46447 | F154: =IF(ISNUMBER(Tracker!L153),Tracker!L153,IF(ISNUMBER(Tracker!K153),Tracker!K153,0)) -> 46447 | DU154: =Tracker!M153 -> No Update Received
A155: =Tracker!F154 -> KM.126 | B155: =Tracker!G154 -> Venue Management On- Site Operations Commence | C155: =TRIM(Tracker!D154) -> Event & Venue Management | D155: =IF(TRIM(Tracker!J154)="",Tracker!I154,Tracker!J154) -> Department Led | E155: =IF(ISNUMBER(Tracker!K154),Tracker!K154,IF(ISNUMBER(Tracker!L154),Tracker!L154,0)) -> 46508 | F155: =IF(ISNUMBER(Tracker!L154),Tracker!L154,IF(ISNUMBER(Tracker!K154),Tracker!K154,0)) -> 46508 | DU155: =Tracker!M154 -> No Update Received
A156: =Tracker!F155 -> KM.137 | B156: =Tracker!G155 -> All Venues Fitness Certificate Approved | C156: =TRIM(Tracker!D155) -> Event & Venue Management | D156: =IF(TRIM(Tracker!J155)="",Tracker!I155,Tracker!J155) -> Department Led | E156: =IF(ISNUMBER(Tracker!K155),Tracker!K155,IF(ISNUMBER(Tracker!L155),Tracker!L155,0)) -> 0 | F156: =IF(ISNUMBER(Tracker!L155),Tracker!L155,IF(ISNUMBER(Tracker!K155),Tracker!K155,0)) -> 0 | DU156: =Tracker!M155 -> No Update Received
A157: =Tracker!F156 -> KM.138 | B157: =Tracker!G156 -> Final All International Participants Operating Plans Approved | C157: =TRIM(Tracker!D156) -> Event & Venue Management | D157: =IF(TRIM(Tracker!J156)="",Tracker!I156,Tracker!J156) -> Department Led | E157: =IF(ISNUMBER(Tracker!K156),Tracker!K156,IF(ISNUMBER(Tracker!L156),Tracker!L156,0)) -> 0 | F157: =IF(ISNUMBER(Tracker!L156),Tracker!L156,IF(ISNUMBER(Tracker!K156),Tracker!K156,0)) -> 0 | DU157: =Tracker!M156 -> No Update Received
A158: =Tracker!F157 -> KM.139 | B158: =Tracker!G157 -> Final C4 Conops Approved | C158: =TRIM(Tracker!D157) -> Event & Venue Management | D158: =IF(TRIM(Tracker!J157)="",Tracker!I157,Tracker!J157) -> Department Led | E158: =IF(ISNUMBER(Tracker!K157),Tracker!K157,IF(ISNUMBER(Tracker!L157),Tracker!L157,0)) -> 0 | F158: =IF(ISNUMBER(Tracker!L157),Tracker!L157,IF(ISNUMBER(Tracker!K157),Tracker!K157,0)) -> 0 | DU158: =Tracker!M157 -> No Update Received
...
